<sdf version='1.6'>
  <world name='default'>
    <light name='sun' type='directional'>
      <cast_shadows>1</cast_shadows>
      <pose frame=''>0 0 10 0 -0 0</pose>
      <diffuse>0.8 0.8 0.8 1</diffuse>
      <specular>0.1 0.1 0.1 1</specular>
      <attenuation>
        <range>1000</range>
        <constant>0.9</constant>
        <linear>0.01</linear>
        <quadratic>0.001</quadratic>
      </attenuation>
      <direction>-0.5 0.5 -1</direction>
    </light>
    <model name='ground_plane'>
      <static>1</static>
      <link name='link'>
        <collision name='collision'>
          <geometry>
            <plane>
              <normal>0 0 1</normal>
              <size>100 100</size>
            </plane>
          </geometry>
          <surface>
            <friction>
              <ode>
                <mu>100</mu>
                <mu2>50</mu2>
              </ode>
              <torsional>
                <ode/>
              </torsional>
            </friction>
            <contact>
              <ode/>
            </contact>
            <bounce/>
          </surface>
          <max_contacts>10</max_contacts>
        </collision>
        <visual name='visual'>
          <cast_shadows>0</cast_shadows>
          <geometry>
            <plane>
              <normal>0 0 1</normal>
              <size>100 100</size>
            </plane>
          </geometry>
          <material>
            <script>
              <uri>file://media/materials/scripts/gazebo.material</uri>
              <name>Gazebo/Grey</name>
            </script>
          </material>
        </visual>
        <self_collide>0</self_collide>
        <kinematic>0</kinematic>
        <gravity>1</gravity>
      </link>
    </model>
    <gravity>0 0 -9.8</gravity>
    <magnetic_field>6e-06 2.3e-05 -4.2e-05</magnetic_field>
    <atmosphere type='adiabatic'/>
    <physics name='default_physics' default='0' type='ode'>
      <max_step_size>0.001</max_step_size>
      <real_time_factor>1</real_time_factor>
      <real_time_update_rate>1000</real_time_update_rate>
    </physics>
    <scene>
      <ambient>0.4 0.4 0.4 1</ambient>
      <background>0.7 0.7 0.7 1</background>
      <shadows>1</shadows>
    </scene>
    <spherical_coordinates>
      <surface_model>EARTH_WGS84</surface_model>
      <latitude_deg>0</latitude_deg>
      <longitude_deg>0</longitude_deg>
      <elevation>0</elevation>
      <heading_deg>0</heading_deg>
    </spherical_coordinates>
    <model name='nist'>
      <static>1</static>
      <link name='nist_maze_wall_triple_holes_120_link'>
        <pose frame=''>0 0 0 0 -0 0</pose>
        <collision name='collision'>
          <geometry>
            <mesh>
              <uri>model://nist_maze_wall_triple_holes_120/meshes/nist_maze_wall_triple_holes_120.dae</uri>
              <scale>1 1 1</scale>
            </mesh>
          </geometry>
          <max_contacts>10</max_contacts>
          <surface>
            <contact>
              <ode/>
            </contact>
            <bounce/>
            <friction>
              <torsional>
                <ode/>
              </torsional>
              <ode/>
            </friction>
          </surface>
        </collision>
        <visual name='visual'>
          <geometry>
            <mesh>
              <uri>model://nist_maze_wall_triple_holes_120/meshes/nist_maze_wall_triple_holes_120.dae</uri>
              <scale>1 1 1</scale>
            </mesh>
          </geometry>
        </visual>
        <self_collide>0</self_collide>
        <kinematic>0</kinematic>
        <gravity>1</gravity>
      </link>
      <pose frame=''>0.727589 -2.57008 0 0 -0 0</pose>
    </model>
    <model name='nist_clone'>
      <static>1</static>
      <link name='nist_maze_wall_triple_holes_120_link'>
        <pose frame=''>0 0 0 0 -0 0</pose>
        <collision name='collision'>
          <geometry>
            <mesh>
              <uri>model://nist_maze_wall_triple_holes_120/meshes/nist_maze_wall_triple_holes_120.dae</uri>
              <scale>1 1 1</scale>
            </mesh>
          </geometry>
          <max_contacts>10</max_contacts>
          <surface>
            <contact>
              <ode/>
            </contact>
            <bounce/>
            <friction>
              <torsional>
                <ode/>
              </torsional>
              <ode/>
            </friction>
          </surface>
        </collision>
        <visual name='visual'>
          <geometry>
            <mesh>
              <uri>model://nist_maze_wall_triple_holes_120/meshes/nist_maze_wall_triple_holes_120.dae</uri>
              <scale>1 1 1</scale>
            </mesh>
          </geometry>
        </visual>
        <self_collide>0</self_collide>
        <kinematic>0</kinematic>
        <gravity>1</gravity>
      </link>
      <pose frame=''>1.94695 -2.58281 0 0 -0 0</pose>
    </model>
    <model name='nist_clone_0'>
      <static>1</static>
      <link name='nist_maze_wall_triple_holes_120_link'>
        <pose frame=''>0 0 0 0 -0 0</pose>
        <collision name='collision'>
          <geometry>
            <mesh>
              <uri>model://nist_maze_wall_triple_holes_120/meshes/nist_maze_wall_triple_holes_120.dae</uri>
              <scale>1 1 1</scale>
            </mesh>
          </geometry>
          <max_contacts>10</max_contacts>
          <surface>
            <contact>
              <ode/>
            </contact>
            <bounce/>
            <friction>
              <torsional>
                <ode/>
              </torsional>
              <ode/>
            </friction>
          </surface>
        </collision>
        <visual name='visual'>
          <geometry>
            <mesh>
              <uri>model://nist_maze_wall_triple_holes_120/meshes/nist_maze_wall_triple_holes_120.dae</uri>
              <scale>1 1 1</scale>
            </mesh>
          </geometry>
        </visual>
        <self_collide>0</self_collide>
        <kinematic>0</kinematic>
        <gravity>1</gravity>
      </link>
      <pose frame=''>3.15824 -2.58187 0 0 -0 0</pose>
    </model>
    <model name='nist_clone_1'>
      <static>1</static>
      <link name='nist_maze_wall_triple_holes_120_link'>
        <pose frame=''>0 0 0 0 -0 0</pose>
        <collision name='collision'>
          <geometry>
            <mesh>
              <uri>model://nist_maze_wall_triple_holes_120/meshes/nist_maze_wall_triple_holes_120.dae</uri>
              <scale>1 1 1</scale>
            </mesh>
          </geometry>
          <max_contacts>10</max_contacts>
          <surface>
            <contact>
              <ode/>
            </contact>
            <bounce/>
            <friction>
              <torsional>
                <ode/>
              </torsional>
              <ode/>
            </friction>
          </surface>
        </collision>
        <visual name='visual'>
          <geometry>
            <mesh>
              <uri>model://nist_maze_wall_triple_holes_120/meshes/nist_maze_wall_triple_holes_120.dae</uri>
              <scale>1 1 1</scale>
            </mesh>
          </geometry>
        </visual>
        <self_collide>0</self_collide>
        <kinematic>0</kinematic>
        <gravity>1</gravity>
      </link>
      <pose frame=''>4.36095 -2.57675 0 0 -0 0</pose>
    </model>
    <model name='nist_clone_0_clone'>
      <static>1</static>
      <link name='nist_maze_wall_triple_holes_120_link'>
        <pose frame=''>0 0 0 0 -0 0</pose>
        <collision name='collision'>
          <geometry>
            <mesh>
              <uri>model://nist_maze_wall_triple_holes_120/meshes/nist_maze_wall_triple_holes_120.dae</uri>
              <scale>1 1 1</scale>
            </mesh>
          </geometry>
          <max_contacts>10</max_contacts>
          <surface>
            <contact>
              <ode/>
            </contact>
            <bounce/>
            <friction>
              <torsional>
                <ode/>
              </torsional>
              <ode/>
            </friction>
          </surface>
        </collision>
        <visual name='visual'>
          <geometry>
            <mesh>
              <uri>model://nist_maze_wall_triple_holes_120/meshes/nist_maze_wall_triple_holes_120.dae</uri>
              <scale>1 1 1</scale>
            </mesh>
          </geometry>
        </visual>
        <self_collide>0</self_collide>
        <kinematic>0</kinematic>
        <gravity>1</gravity>
      </link>
      <pose frame=''>0.659887 1.34423 0 0 -0 0</pose>
    </model>
    <model name='nist_clone_0_clone_0'>
      <static>1</static>
      <link name='nist_maze_wall_triple_holes_120_link'>
        <pose frame=''>0 0 0 0 -0 0</pose>
        <collision name='collision'>
          <geometry>
            <mesh>
              <uri>model://nist_maze_wall_triple_holes_120/meshes/nist_maze_wall_triple_holes_120.dae</uri>
              <scale>1 1 1</scale>
            </mesh>
          </geometry>
          <max_contacts>10</max_contacts>
          <surface>
            <contact>
              <ode/>
            </contact>
            <bounce/>
            <friction>
              <torsional>
                <ode/>
              </torsional>
              <ode/>
            </friction>
          </surface>
        </collision>
        <visual name='visual'>
          <geometry>
            <mesh>
              <uri>model://nist_maze_wall_triple_holes_120/meshes/nist_maze_wall_triple_holes_120.dae</uri>
              <scale>1 1 1</scale>
            </mesh>
          </geometry>
        </visual>
        <self_collide>0</self_collide>
        <kinematic>0</kinematic>
        <gravity>1</gravity>
      </link>
      <pose frame=''>1.85906 1.3881 0 0 -0 0</pose>
    </model>
    <model name='nist_clone_0_clone_1'>
      <static>1</static>
      <link name='nist_maze_wall_triple_holes_120_link'>
        <pose frame=''>0 0 0 0 -0 0</pose>
        <collision name='collision'>
          <geometry>
            <mesh>
              <uri>model://nist_maze_wall_triple_holes_120/meshes/nist_maze_wall_triple_holes_120.dae</uri>
              <scale>1 1 1</scale>
            </mesh>
          </geometry>
          <max_contacts>10</max_contacts>
          <surface>
            <contact>
              <ode/>
            </contact>
            <bounce/>
            <friction>
              <torsional>
                <ode/>
              </torsional>
              <ode/>
            </friction>
          </surface>
        </collision>
        <visual name='visual'>
          <geometry>
            <mesh>
              <uri>model://nist_maze_wall_triple_holes_120/meshes/nist_maze_wall_triple_holes_120.dae</uri>
              <scale>1 1 1</scale>
            </mesh>
          </geometry>
        </visual>
        <self_collide>0</self_collide>
        <kinematic>0</kinematic>
        <gravity>1</gravity>
      </link>
      <pose frame=''>3.06013 1.40043 0 0 -0 0</pose>
    </model>
    <model name='nist_clone_0_clone_2'>
      <static>1</static>
      <link name='nist_maze_wall_triple_holes_120_link'>
        <pose frame=''>0 0 0 0 -0 0</pose>
        <collision name='collision'>
          <geometry>
            <mesh>
              <uri>model://nist_maze_wall_triple_holes_120/meshes/nist_maze_wall_triple_holes_120.dae</uri>
              <scale>1 1 1</scale>
            </mesh>
          </geometry>
          <max_contacts>10</max_contacts>
          <surface>
            <contact>
              <ode/>
            </contact>
            <bounce/>
            <friction>
              <torsional>
                <ode/>
              </torsional>
              <ode/>
            </friction>
          </surface>
        </collision>
        <visual name='visual'>
          <geometry>
            <mesh>
              <uri>model://nist_maze_wall_triple_holes_120/meshes/nist_maze_wall_triple_holes_120.dae</uri>
              <scale>1 1 1</scale>
            </mesh>
          </geometry>
        </visual>
        <self_collide>0</self_collide>
        <kinematic>0</kinematic>
        <gravity>1</gravity>
      </link>
      <pose frame=''>4.33493 1.35629 0 0 -0 0</pose>
    </model>
    <model name='nist_clone_0_clone_3'>
      <static>1</static>
      <link name='nist_maze_wall_triple_holes_120_link'>
        <pose frame=''>0 0 0 0 -0 0</pose>
        <collision name='collision'>
          <geometry>
            <mesh>
              <uri>model://nist_maze_wall_triple_holes_120/meshes/nist_maze_wall_triple_holes_120.dae</uri>
              <scale>1 1 1</scale>
            </mesh>
          </geometry>
          <max_contacts>10</max_contacts>
          <surface>
            <contact>
              <ode/>
            </contact>
            <bounce/>
            <friction>
              <torsional>
                <ode/>
              </torsional>
              <ode/>
            </friction>
          </surface>
        </collision>
        <visual name='visual'>
          <geometry>
            <mesh>
              <uri>model://nist_maze_wall_triple_holes_120/meshes/nist_maze_wall_triple_holes_120.dae</uri>
              <scale>1 1 1</scale>
            </mesh>
          </geometry>
        </visual>
        <self_collide>0</self_collide>
        <kinematic>0</kinematic>
        <gravity>1</gravity>
      </link>
      <pose frame=''>5.8028 1.13794 0 0 -0 0</pose>
    </model>
    <model name='nist_clone_0_clone_4'>
      <static>1</static>
      <link name='nist_maze_wall_triple_holes_120_link'>
        <pose frame=''>0 0 0 0 -0 0</pose>
        <collision name='collision'>
          <geometry>
            <mesh>
              <uri>model://nist_maze_wall_triple_holes_120/meshes/nist_maze_wall_triple_holes_120.dae</uri>
              <scale>1 1 1</scale>
            </mesh>
          </geometry>
          <max_contacts>10</max_contacts>
          <surface>
            <contact>
              <ode/>
            </contact>
            <bounce/>
            <friction>
              <torsional>
                <ode/>
              </torsional>
              <ode/>
            </friction>
          </surface>
        </collision>
        <visual name='visual'>
          <geometry>
            <mesh>
              <uri>model://nist_maze_wall_triple_holes_120/meshes/nist_maze_wall_triple_holes_120.dae</uri>
              <scale>1 1 1</scale>
            </mesh>
          </geometry>
        </visual>
        <self_collide>0</self_collide>
        <kinematic>0</kinematic>
        <gravity>1</gravity>
      </link>
      <pose frame=''>7.21392 0.827282 0 0 -0 0</pose>
    </model>
    <model name='nist_clone_0_clone_5'>
      <static>1</static>
      <link name='nist_maze_wall_triple_holes_120_link'>
        <pose frame=''>0 0 0 0 -0 0</pose>
        <collision name='collision'>
          <geometry>
            <mesh>
              <uri>model://nist_maze_wall_triple_holes_120/meshes/nist_maze_wall_triple_holes_120.dae</uri>
              <scale>1 1 1</scale>
            </mesh>
          </geometry>
          <max_contacts>10</max_contacts>
          <surface>
            <contact>
              <ode/>
            </contact>
            <bounce/>
            <friction>
              <torsional>
                <ode/>
              </torsional>
              <ode/>
            </friction>
          </surface>
        </collision>
        <visual name='visual'>
          <geometry>
            <mesh>
              <uri>model://nist_maze_wall_triple_holes_120/meshes/nist_maze_wall_triple_holes_120.dae</uri>
              <scale>1 1 1</scale>
            </mesh>
          </geometry>
        </visual>
        <self_collide>0</self_collide>
        <kinematic>0</kinematic>
        <gravity>1</gravity>
      </link>
      <pose frame=''>8.44583 0.32373 0 0 -0 0</pose>
    </model>
    <model name='nist_clone_0_clone_6'>
      <static>1</static>
      <link name='nist_maze_wall_triple_holes_120_link'>
        <pose frame=''>0 0 0 0 -0 0</pose>
        <collision name='collision'>
          <geometry>
            <mesh>
              <uri>model://nist_maze_wall_triple_holes_120/meshes/nist_maze_wall_triple_holes_120.dae</uri>
              <scale>1 1 1</scale>
            </mesh>
          </geometry>
          <max_contacts>10</max_contacts>
          <surface>
            <contact>
              <ode/>
            </contact>
            <bounce/>
            <friction>
              <torsional>
                <ode/>
              </torsional>
              <ode/>
            </friction>
          </surface>
        </collision>
        <visual name='visual'>
          <geometry>
            <mesh>
              <uri>model://nist_maze_wall_triple_holes_120/meshes/nist_maze_wall_triple_holes_120.dae</uri>
              <scale>1 1 1</scale>
            </mesh>
          </geometry>
        </visual>
        <self_collide>0</self_collide>
        <kinematic>0</kinematic>
        <gravity>1</gravity>
      </link>
      <pose frame=''>9.60009 -0.147979 0 0 -0 0</pose>
    </model>
    <model name='nist_clone_0_clone_7'>
      <static>1</static>
      <link name='nist_maze_wall_triple_holes_120_link'>
        <pose frame=''>0 0 0 0 -0 0</pose>
        <collision name='collision'>
          <geometry>
            <mesh>
              <uri>model://nist_maze_wall_triple_holes_120/meshes/nist_maze_wall_triple_holes_120.dae</uri>
              <scale>1 1 1</scale>
            </mesh>
          </geometry>
          <max_contacts>10</max_contacts>
          <surface>
            <contact>
              <ode/>
            </contact>
            <bounce/>
            <friction>
              <torsional>
                <ode/>
              </torsional>
              <ode/>
            </friction>
          </surface>
        </collision>
        <visual name='visual'>
          <geometry>
            <mesh>
              <uri>model://nist_maze_wall_triple_holes_120/meshes/nist_maze_wall_triple_holes_120.dae</uri>
              <scale>1 1 1</scale>
            </mesh>
          </geometry>
        </visual>
        <self_collide>0</self_collide>
        <kinematic>0</kinematic>
        <gravity>1</gravity>
      </link>
      <pose frame=''>5.41627 -2.70041 0 0 -0 0</pose>
    </model>
    <model name='nist_clone_0_clone_8'>
      <static>1</static>
      <link name='nist_maze_wall_triple_holes_120_link'>
        <pose frame=''>0 0 0 0 -0 0</pose>
        <collision name='collision'>
          <geometry>
            <mesh>
              <uri>model://nist_maze_wall_triple_holes_120/meshes/nist_maze_wall_triple_holes_120.dae</uri>
              <scale>1 1 1</scale>
            </mesh>
          </geometry>
          <max_contacts>10</max_contacts>
          <surface>
            <contact>
              <ode/>
            </contact>
            <bounce/>
            <friction>
              <torsional>
                <ode/>
              </torsional>
              <ode/>
            </friction>
          </surface>
        </collision>
        <visual name='visual'>
          <geometry>
            <mesh>
              <uri>model://nist_maze_wall_triple_holes_120/meshes/nist_maze_wall_triple_holes_120.dae</uri>
              <scale>1 1 1</scale>
            </mesh>
          </geometry>
        </visual>
        <self_collide>0</self_collide>
        <kinematic>0</kinematic>
        <gravity>1</gravity>
      </link>
      <pose frame=''>6.63705 -2.90101 0 0 -0 0</pose>
    </model>
    <model name='nist_clone_0_clone_9'>
      <static>1</static>
      <link name='nist_maze_wall_triple_holes_120_link'>
        <pose frame=''>0 0 0 0 -0 0</pose>
        <collision name='collision'>
          <geometry>
            <mesh>
              <uri>model://nist_maze_wall_triple_holes_120/meshes/nist_maze_wall_triple_holes_120.dae</uri>
              <scale>1 1 1</scale>
            </mesh>
          </geometry>
          <max_contacts>10</max_contacts>
          <surface>
            <contact>
              <ode/>
            </contact>
            <bounce/>
            <friction>
              <torsional>
                <ode/>
              </torsional>
              <ode/>
            </friction>
          </surface>
        </collision>
        <visual name='visual'>
          <geometry>
            <mesh>
              <uri>model://nist_maze_wall_triple_holes_120/meshes/nist_maze_wall_triple_holes_120.dae</uri>
              <scale>1 1 1</scale>
            </mesh>
          </geometry>
        </visual>
        <self_collide>0</self_collide>
        <kinematic>0</kinematic>
        <gravity>1</gravity>
      </link>
      <pose frame=''>7.92011 -3.17566 0 0 -0 0</pose>
    </model>
    <model name='nist_clone_0_clone_10'>
      <static>1</static>
      <link name='nist_maze_wall_triple_holes_120_link'>
        <pose frame=''>0 0 0 0 -0 0</pose>
        <collision name='collision'>
          <geometry>
            <mesh>
              <uri>model://nist_maze_wall_triple_holes_120/meshes/nist_maze_wall_triple_holes_120.dae</uri>
              <scale>1 1 1</scale>
            </mesh>
          </geometry>
          <max_contacts>10</max_contacts>
          <surface>
            <contact>
              <ode/>
            </contact>
            <bounce/>
            <friction>
              <torsional>
                <ode/>
              </torsional>
              <ode/>
            </friction>
          </surface>
        </collision>
        <visual name='visual'>
          <geometry>
            <mesh>
              <uri>model://nist_maze_wall_triple_holes_120/meshes/nist_maze_wall_triple_holes_120.dae</uri>
              <scale>1 1 1</scale>
            </mesh>
          </geometry>
        </visual>
        <self_collide>0</self_collide>
        <kinematic>0</kinematic>
        <gravity>1</gravity>
      </link>
      <pose frame=''>9.24463 -3.43527 0 0 -0 0</pose>
    </model>
    <model name='nist_clone_0_clone_11'>
      <static>1</static>
      <link name='nist_maze_wall_triple_holes_120_link'>
        <pose frame=''>0 0 0 0 -0 0</pose>
        <collision name='collision'>
          <geometry>
            <mesh>
              <uri>model://nist_maze_wall_triple_holes_120/meshes/nist_maze_wall_triple_holes_120.dae</uri>
              <scale>1 1 1</scale>
            </mesh>
          </geometry>
          <max_contacts>10</max_contacts>
          <surface>
            <contact>
              <ode/>
            </contact>
            <bounce/>
            <friction>
              <torsional>
                <ode/>
              </torsional>
              <ode/>
            </friction>
          </surface>
        </collision>
        <visual name='visual'>
          <geometry>
            <mesh>
              <uri>model://nist_maze_wall_triple_holes_120/meshes/nist_maze_wall_triple_holes_120.dae</uri>
              <scale>1 1 1</scale>
            </mesh>
          </geometry>
        </visual>
        <self_collide>0</self_collide>
        <kinematic>0</kinematic>
        <gravity>1</gravity>
      </link>
      <pose frame=''>10.3676 -3.60469 0 0 -0 0</pose>
    </model>
    <model name='nist_clone_0_clone_12'>
      <static>1</static>
      <link name='nist_maze_wall_triple_holes_120_link'>
        <pose frame=''>0 0 0 0 -0 0</pose>
        <collision name='collision'>
          <geometry>
            <mesh>
              <uri>model://nist_maze_wall_triple_holes_120/meshes/nist_maze_wall_triple_holes_120.dae</uri>
              <scale>1 1 1</scale>
            </mesh>
          </geometry>
          <max_contacts>10</max_contacts>
          <surface>
            <contact>
              <ode/>
            </contact>
            <bounce/>
            <friction>
              <torsional>
                <ode/>
              </torsional>
              <ode/>
            </friction>
          </surface>
        </collision>
        <visual name='visual'>
          <geometry>
            <mesh>
              <uri>model://nist_maze_wall_triple_holes_120/meshes/nist_maze_wall_triple_holes_120.dae</uri>
              <scale>1 1 1</scale>
            </mesh>
          </geometry>
        </visual>
        <self_collide>0</self_collide>
        <kinematic>0</kinematic>
        <gravity>1</gravity>
      </link>
      <pose frame=''>10.7489 -0.539838 0 0 -0 0</pose>
    </model>
    <model name='nist_clone_0_clone_13'>
      <static>1</static>
      <link name='nist_maze_wall_triple_holes_120_link'>
        <pose frame=''>0 0 0 0 -0 0</pose>
        <collision name='collision'>
          <geometry>
            <mesh>
              <uri>model://nist_maze_wall_triple_holes_120/meshes/nist_maze_wall_triple_holes_120.dae</uri>
              <scale>1 1 1</scale>
            </mesh>
          </geometry>
          <max_contacts>10</max_contacts>
          <surface>
            <contact>
              <ode/>
            </contact>
            <bounce/>
            <friction>
              <torsional>
                <ode/>
              </torsional>
              <ode/>
            </friction>
          </surface>
        </collision>
        <visual name='visual'>
          <geometry>
            <mesh>
              <uri>model://nist_maze_wall_triple_holes_120/meshes/nist_maze_wall_triple_holes_120.dae</uri>
              <scale>1 1 1</scale>
            </mesh>
          </geometry>
        </visual>
        <self_collide>0</self_collide>
        <kinematic>0</kinematic>
        <gravity>1</gravity>
      </link>
      <pose frame=''>12.2332 -1.07191 0 0 -0 0</pose>
    </model>
    <state world_name='default'>
      <sim_time>1118 917000000</sim_time>
      <real_time>576 436637204</real_time>
      <wall_time>1505151645 279782585</wall_time>
      <iterations>573204</iterations>
      <model name='ground_plane'>
        <pose frame=''>0 0 0 0 -0 0</pose>
        <scale>1 1 1</scale>
        <link name='link'>
          <pose frame=''>0 0 0 0 -0 0</pose>
          <velocity>0 0 0 0 -0 0</velocity>
          <acceleration>0 0 0 0 -0 0</acceleration>
          <wrench>0 0 0 0 -0 0</wrench>
        </link>
      </model>

      <model name='nist'>
        <pose frame=''>0.727589 -2.57008 0 0 -0 0</pose>
        <scale>1 1 1</scale>
        <link name='nist_maze_wall_triple_holes_120_link'>
          <pose frame=''>0.727589 -2.57008 0 0 -0 0</pose>
          <velocity>0 0 0 0 -0 0</velocity>
          <acceleration>0 0 0 0 -0 0</acceleration>
          <wrench>0 0 0 0 -0 0</wrench>
        </link>
      </model>
      <model name='nist_clone'>
        <pose frame=''>1.94695 -2.57008 0 0 -0 0</pose>
        <scale>1 1 1</scale>
        <link name='nist_maze_wall_triple_holes_120_link'>
          <pose frame=''>1.94695 -2.57008 0 0 -0 0</pose>
          <velocity>0 0 0 0 -0 0</velocity>
          <acceleration>0 0 0 0 -0 0</acceleration>
          <wrench>0 0 0 0 -0 0</wrench>
        </link>
      </model>
      <model name='nist_clone_0'>
        <pose frame=''>3.15824 -2.57008 0 0 -0 0</pose>
        <scale>1 1 1</scale>
        <link name='nist_maze_wall_triple_holes_120_link'>
          <pose frame=''>3.15824 -2.57008 0 0 -0 0</pose>
          <velocity>0 0 0 0 -0 0</velocity>
          <acceleration>0 0 0 0 -0 0</acceleration>
          <wrench>0 0 0 0 -0 0</wrench>
        </link>
      </model>
      <model name='nist_clone_0_clone'>
        <pose frame=''>0.659887 1.13794 0 0 -0 0</pose>
        <scale>1 1 1</scale>
        <link name='nist_maze_wall_triple_holes_120_link'>
          <pose frame=''>0.659887 1.13794 0 0 -0 0</pose>
          <velocity>0 0 0 0 -0 0</velocity>
          <acceleration>0 0 0 0 -0 0</acceleration>
          <wrench>0 0 0 0 -0 0</wrench>
        </link>
      </model>
      <model name='nist_clone_0_clone_0'>
        <pose frame=''>1.85906 1.13794 0 0 -0 0</pose>
        <scale>1 1 1</scale>
        <link name='nist_maze_wall_triple_holes_120_link'>
          <pose frame=''>1.85906 1.13794 0 0 -0 0</pose>
          <velocity>0 0 0 0 -0 0</velocity>
          <acceleration>0 0 0 0 -0 0</acceleration>
          <wrench>0 0 0 0 -0 0</wrench>
        </link>
      </model>
      <model name='nist_clone_0_clone_1'>
        <pose frame=''>3.06013 1.13794 0 0 -0 0</pose>
        <scale>1 1 1</scale>
        <link name='nist_maze_wall_triple_holes_120_link'>
          <pose frame=''>3.06013 1.13794 0 0 -0 0</pose>
          <velocity>0 0 0 0 -0 0</velocity>
          <acceleration>0 0 0 0 -0 0</acceleration>
          <wrench>0 0 0 0 -0 0</wrench>
        </link>
      </model>
      <model name='nist_clone_0_clone_10'>
        <pose frame=''>9.24463 -2.57008 0 0 -0 0</pose>
        <scale>1 1 1</scale>
        <link name='nist_maze_wall_triple_holes_120_link'>
          <pose frame=''>9.24463 -2.57008 0 0 -0 0</pose>
          <velocity>0 0 0 0 -0 0</velocity>
          <acceleration>0 0 0 0 -0 0</acceleration>
          <wrench>0 0 0 0 -0 0</wrench>
        </link>
      </model>
      <model name='nist_clone_0_clone_11'>
        <pose frame=''>11 -2.57008 0 0 -0 0</pose>
        <scale>1 1 1</scale>
        <link name='nist_maze_wall_triple_holes_120_link'>
          <pose frame=''>11 -2.57008 0 0 -0 0</pose>
          <velocity>0 0 0 0 -0 0</velocity>
          <acceleration>0 0 0 0 -0 0</acceleration>
          <wrench>0 0 0 0 -0 0</wrench>
        </link>
      </model>
      <model name='nist_clone_0_clone_12'>
        <pose frame=''>10.7489 1.13794 0 0 -0 0</pose>
        <scale>1 1 1</scale>
        <link name='nist_maze_wall_triple_holes_120_link'>
          <pose frame=''>10.7489 1.13794 0 0 -0 0</pose>
          <velocity>0 0 0 0 -0 0</velocity>
          <acceleration>0 0 0 0 -0 0</acceleration>
          <wrench>0 0 0 0 -0 0</wrench>
        </link>
      </model>
      <model name='nist_clone_0_clone_13'>
        <pose frame=''>12.2332 1.13794 0 0 -0 0</pose>
        <scale>1 1 1</scale>
        <link name='nist_maze_wall_triple_holes_120_link'>
          <pose frame=''>12.2332 1.13794 0 0 -0 0</pose>
          <velocity>0 0 0 0 -0 0</velocity>
          <acceleration>0 0 0 0 -0 0</acceleration>
          <wrench>0 0 0 0 -0 0</wrench>
        </link>
      </model>
      <model name='nist_clone_0_clone_2'>
        <pose frame=''>4.33493 1.13794 0 0 -0 0</pose>
        <scale>1 1 1</scale>
        <link name='nist_maze_wall_triple_holes_120_link'>
          <pose frame=''>4.33493 1.13794 0 0 -0 0</pose>
          <velocity>0 0 0 0 -0 0</velocity>
          <acceleration>0 0 0 0 -0 0</acceleration>
          <wrench>0 0 0 0 -0 0</wrench>
        </link>
      </model>
      <model name='nist_clone_0_clone_3'>
        <pose frame=''>5.8028 1.13794 0 0 -0 0</pose>
        <scale>1 1 1</scale>
        <link name='nist_maze_wall_triple_holes_120_link'>
          <pose frame=''>5.8028 1.13794 0 0 -0 0</pose>
          <velocity>0 0 0 0 -0 0</velocity>
          <acceleration>0 0 0 0 -0 0</acceleration>
          <wrench>0 0 0 0 -0 0</wrench>
        </link>
      </model>
      <model name='nist_clone_0_clone_4'>
        <pose frame=''>7.21392 1.13794 0 0 -0 0</pose>
        <scale>1 1 1</scale>
        <link name='nist_maze_wall_triple_holes_120_link'>
          <pose frame=''>7.21392 1.13794 0 0 -0 0</pose>
          <velocity>0 0 0 0 -0 0</velocity>
          <acceleration>0 0 0 0 -0 0</acceleration>
          <wrench>0 0 0 0 -0 0</wrench>
        </link>
      </model>
      <model name='nist_clone_0_clone_5'>
        <pose frame=''>8.44583 1.13794 0 0 -0 0</pose>
        <scale>1 1 1</scale>
        <link name='nist_maze_wall_triple_holes_120_link'>
          <pose frame=''>8.44583 1.13794 0 0 -0 0</pose>
          <velocity>0 0 0 0 -0 0</velocity>
          <acceleration>0 0 0 0 -0 0</acceleration>
          <wrench>0 0 0 0 -0 0</wrench>
        </link>
      </model>
      <model name='nist_clone_0_clone_6'>
        <pose frame=''>9.60009 1.13794 0 0 -0 0</pose>
        <scale>1 1 1</scale>
        <link name='nist_maze_wall_triple_holes_120_link'>
          <pose frame=''>9.60009 1.13794 0 0 -0 0</pose>
          <velocity>0 0 0 0 -0 0</velocity>
          <acceleration>0 0 0 0 -0 0</acceleration>
          <wrench>0 0 0 0 -0 0</wrench>
        </link>
      </model>
      <model name='nist_clone_0_clone_7'>
        <pose frame=''>5.41627 -2.57008 0 0 -0 0</pose>
        <scale>1 1 1</scale>
        <link name='nist_maze_wall_triple_holes_120_link'>
          <pose frame=''>5.41627 -2.57008 0 0 -0 0</pose>
          <velocity>0 0 0 0 -0 0</velocity>
          <acceleration>0 0 0 0 -0 0</acceleration>
          <wrench>0 0 0 0 -0 0</wrench>
        </link>
      </model>
      <model name='nist_clone_0_clone_8'>
        <pose frame=''>6.63705 -2.57008 0 0 -0 0</pose>
        <scale>1 1 1</scale>
        <link name='nist_maze_wall_triple_holes_120_link'>
          <pose frame=''>6.63705 -2.57008 0 0 -0 0</pose>
          <velocity>0 0 0 0 -0 0</velocity>
          <acceleration>0 0 0 0 -0 0</acceleration>
          <wrench>0 0 0 0 -0 0</wrench>
        </link>
      </model>
      <model name='nist_clone_0_clone_9'>
        <pose frame=''>7.92011 -2.57008 0 0 -0 0</pose>
        <scale>1 1 1</scale>
        <link name='nist_maze_wall_triple_holes_120_link'>
          <pose frame=''>7.92011 -2.57008 0 0 -0 0</pose>
          <velocity>0 0 0 0 -0 0</velocity>
          <acceleration>0 0 0 0 -0 0</acceleration>
          <wrench>0 0 0 0 -0 0</wrench>
        </link>
      </model>
      <model name='nist_clone_1'>
        <pose frame=''>4.36095 -2.57008 0 0 -0 0</pose>
        <scale>1 1 1</scale>
        <link name='nist_maze_wall_triple_holes_120_link'>
          <pose frame=''>4.36095 -2.57008 0 0 -0 0</pose>
          <velocity>0 0 0 0 -0 0</velocity>
          <acceleration>0 0 0 0 -0 0</acceleration>
          <wrench>0 0 0 0 -0 0</wrench>
        </link>
      </model>
      <light name='sun'>
        <pose frame=''>0 0 10 0 -0 0</pose>
      </light>
    </state>
    <gui fullscreen='0'>
      <camera name='user_camera'>
        <pose frame=''>14.0971 -4.02975 31.2222 -0 1.23094 -2.91767</pose>
        <view_controller>orbit</view_controller>
        <projection_type>perspective</projection_type>
      </camera>
    </gui>
    <model name='mkz'>
      <link name='base_footprint'>
        <pose frame=''>0 0 0 0 -0 0</pose>
        <inertial>
          <pose frame=''>1.42195 0 0.58058 0 -0 0</pose>
          <mass>1501</mass>
          <inertia>
            <ixx>1000.79</ixx>
            <ixy>0</ixy>
            <ixz>0.715098</ixz>
            <iyy>1001.47</iyy>
            <iyz>0</iyz>
            <izz>1000.74</izz>
          </inertia>
        </inertial>
        <collision name='base_footprint_fixed_joint_lump__chassis_collision_collision'>
          <pose frame=''>1.51 -0.03046 0.680609 1.5708 -0 3.14159</pose>
          <geometry>
            <mesh>
              <scale>1 1 1</scale>
              <uri>/home/lucas/dbw_ws/src/dbw_mkz_ros/dbw_mkz_description/meshes/body_collision.stl</uri>
            </mesh>
          </geometry>
          <max_contacts>10</max_contacts>
          <surface>
            <contact>
              <ode/>
            </contact>
            <bounce/>
            <friction>
              <torsional>
                <ode/>
              </torsional>
              <ode/>
            </friction>
          </surface>
        </collision>
        <collision name='base_footprint_fixed_joint_lump__perfect_gps_collision_1'>
          <pose frame=''>0.6 0 1.45 0 -0 0</pose>
          <geometry>
            <cylinder>
              <length>0.05</length>
              <radius>0.1</radius>
            </cylinder>
          </geometry>
          <max_contacts>10</max_contacts>
          <surface>
            <contact>
              <ode/>
            </contact>
            <bounce/>
            <friction>
              <torsional>
                <ode/>
              </torsional>
              <ode/>
            </friction>
          </surface>
        </collision>
        <visual name='base_footprint_fixed_joint_lump__chassis_visual'>
          <pose frame=''>1.3641 0 0 0 -0 1.5708</pose>
          <geometry>
            <mesh>
              <scale>1 1 1</scale>
              <uri>file:///tmp/tmp7xnoRG.dae</uri>
            </mesh>
          </geometry>
        </visual>
        <visual name='base_footprint_fixed_joint_lump__front_camera_visual_1'>
          <pose frame=''>2 0 1.3 -2.1708 0 -1.5708</pose>
          <geometry>
            <box>
              <size>0.1 0.1 0.1</size>
            </box>
          </geometry>
        </visual>
        <visual name='base_footprint_fixed_joint_lump__hokuyo_link_visual_2'>
          <pose frame=''>4 0 0.6 0 -0 0</pose>
          <geometry>
            <box>
              <size>0.01 0.05 0.06</size>
            </box>
          </geometry>
          <material>
            <script>
              <uri>__default__</uri>
              <name>__default__</name>
            </script>
          </material>
        </visual>
        <visual name='base_footprint_fixed_joint_lump__perfect_gps_visual_3'>
          <pose frame=''>0.6 0 1.45 0 -0 0</pose>
          <geometry>
            <cylinder>
              <length>0.05</length>
              <radius>0.1</radius>
            </cylinder>
          </geometry>
        </visual>
        <velocity_decay/>
        <velocity_decay/>
        <sensor name='front_camera_camera' type='camera'>
          <update_rate>30</update_rate>
          <camera name='cam'>
            <horizontal_fov>1.39626</horizontal_fov>
            <image>
              <width>800</width>
              <height>800</height>
              <format>R8G8B8</format>
            </image>
            <clip>
              <near>0.02</near>
              <far>300</far>
            </clip>
            <noise>
              <type>gaussian</type>
              <mean>0</mean>
              <stddev>0.007</stddev>
            </noise>
          </camera>
          <plugin name='camera_controller' filename='libgazebo_ros_camera.so'>
            <alwaysOn>true</alwaysOn>
            <updateRate>0.0</updateRate>
            <cameraName>front_camera</cameraName>
            <imageTopicName>image_raw</imageTopicName>
            <cameraInfoTopicName>camera_info</cameraInfoTopicName>
            <frameName>front_camera</frameName>
            <hackBaseline>0.0</hackBaseline>
            <distortionK1>0.0</distortionK1>
            <distortionK2>0.0</distortionK2>
            <distortionK3>0.0</distortionK3>
            <distortionT1>0.0</distortionT1>
            <distortionT2>0.0</distortionT2>
            <robotNamespace>mkz</robotNamespace>
          </plugin>
          <pose frame=''>2 0 1.3 0 0.6 0</pose>
        </sensor>
        <gravity>1</gravity>
        <velocity_decay/>
        <self_collide>0</self_collide>
        <sensor name='hokuyo' type='gpu_ray'>
          <visualize>1</visualize>
          <update_rate>10</update_rate>
          <ray>
            <scan>
              <horizontal>
                <samples>180</samples>
                <resolution>1</resolution>
                <min_angle>-1.5708</min_angle>
                <max_angle>1.5708</max_angle>
              </horizontal>
            </scan>
            <range>
              <min>0.1</min>
              <max>30</max>
              <resolution>0.01</resolution>
            </range>
          </ray>
          <plugin name='hokuyo_hokuyo_node' filename='libgazebo_ros_gpu_laser.so'>
            <topicName>scan</topicName>
            <frameName>hokuyo_link</frameName>
            <robotNamespace>mkz</robotNamespace>
          </plugin>
          <pose frame=''>4 0 0.6 0 -0 0</pose>
        </sensor>
        <kinematic>0</kinematic>
      </link>
      <link name='steer_fl'>
        <pose frame=''>2.85 0.79121 0.33 0 -0 0</pose>
        <inertial>
          <pose frame=''>-0.013054 -0.0295 0 0 -0 0</pose>
          <mass>1</mass>
          <inertia>
            <ixx>0.037227</ixx>
            <ixy>0</ixy>
            <ixz>0</ixz>
            <iyy>0.04</iyy>
            <iyz>0</iyz>
            <izz>0.06</izz>
          </inertia>
        </inertial>
        <self_collide>0</self_collide>
        <kinematic>0</kinematic>
        <gravity>1</gravity>
      </link>
      <joint name='steer_fl' type='revolute'>
        <child>steer_fl</child>
        <parent>base_footprint</parent>
        <axis>
          <xyz>0 0 1</xyz>
          <limit>
            <lower>-0.6</lower>
            <upper>0.6</upper>
            <effort>0</effort>
            <velocity>0</velocity>
          </limit>
          <dynamics>
            <spring_reference>0</spring_reference>
            <spring_stiffness>0</spring_stiffness>
          </dynamics>
          <use_parent_model_frame>1</use_parent_model_frame>
        </axis>
      </joint>
      <link name='wheel_fl'>
        <pose frame=''>2.85 0.79121 0.33 1.5708 -0 3.14159</pose>
        <inertial>
          <pose frame=''>0 0 0 -3.14159 -0 -3.14159</pose>
          <mass>10</mass>
          <inertia>
            <ixx>0.305583</ixx>
            <ixy>0</ixy>
            <ixz>0</ixz>
            <iyy>0.305583</iyy>
            <iyz>0</iyz>
            <izz>0.5445</izz>
          </inertia>
        </inertial>
        <collision name='wheel_fl_collision_collision'>
          <pose frame=''>0 0 0 -3.14159 -0 -3.14159</pose>
          <geometry>
            <cylinder>
              <length>0.2</length>
              <radius>0.33</radius>
            </cylinder>
          </geometry>
          <surface>
            <contact>
              <ode/>
            </contact>
            <friction>
              <ode>
                <mu>1.2</mu>
                <mu2>1.2</mu2>
              </ode>
              <torsional>
                <ode/>
              </torsional>
            </friction>
            <bounce/>
          </surface>
          <max_contacts>10</max_contacts>
        </collision>
        <visual name='wheel_fl_visual_visual'>
          <pose frame=''>0 0 0.0385 3.14159 -1.57079 1.57079</pose>
          <geometry>
            <mesh>
              <scale>1 1 1</scale>
              <uri>/home/lucas/dbw_ws/src/dbw_mkz_ros/dbw_mkz_description/meshes/mkz_13/wheel.dae</uri>
            </mesh>
          </geometry>
          <material>
            <script>
              <uri>__default__</uri>
              <name>__default__</name>
            </script>
          </material>
        </visual>
        <gravity>1</gravity>
        <velocity_decay/>
        <self_collide>0</self_collide>
        <kinematic>0</kinematic>
      </link>
      <joint name='wheel_fl' type='revolute'>
        <child>wheel_fl</child>
        <parent>steer_fl</parent>
        <axis>
          <xyz>0 1 0</xyz>
          <limit>
            <lower>-1e+16</lower>
            <upper>1e+16</upper>
          </limit>
          <dynamics>
            <spring_reference>0</spring_reference>
            <spring_stiffness>0</spring_stiffness>
          </dynamics>
          <use_parent_model_frame>1</use_parent_model_frame>
        </axis>
        <physics>
          <ode>
            <limit>
              <cfm>0</cfm>
              <erp>0.2</erp>
            </limit>
          </ode>
        </physics>
      </joint>
      <link name='steer_fr'>
        <pose frame=''>2.85 -0.79121 0.33 0 -0 0</pose>
        <inertial>
          <pose frame=''>-0.01305 0.0275 0 0 -0 0</pose>
          <mass>1</mass>
          <inertia>
            <ixx>0.037227</ixx>
            <ixy>0</ixy>
            <ixz>0</ixz>
            <iyy>0.04</iyy>
            <iyz>0</iyz>
            <izz>0.06</izz>
          </inertia>
        </inertial>
        <self_collide>0</self_collide>
        <kinematic>0</kinematic>
        <gravity>1</gravity>
      </link>
      <joint name='steer_fr' type='revolute'>
        <child>steer_fr</child>
        <parent>base_footprint</parent>
        <axis>
          <xyz>0 0 1</xyz>
          <limit>
            <lower>-0.6</lower>
            <upper>0.6</upper>
            <effort>0</effort>
            <velocity>0</velocity>
          </limit>
          <dynamics>
            <spring_reference>0</spring_reference>
            <spring_stiffness>0</spring_stiffness>
          </dynamics>
          <use_parent_model_frame>1</use_parent_model_frame>
        </axis>
      </joint>
      <link name='wheel_fr'>
        <pose frame=''>2.85 -0.79121 0.33 1.5708 -0 3.14159</pose>
        <inertial>
          <pose frame=''>0 0 0 3.14159 -0 3.14159</pose>
          <mass>10</mass>
          <inertia>
            <ixx>0.305583</ixx>
            <ixy>0</ixy>
            <ixz>0</ixz>
            <iyy>0.305583</iyy>
            <iyz>0</iyz>
            <izz>0.5445</izz>
          </inertia>
        </inertial>
        <collision name='wheel_fr_collision_collision'>
          <pose frame=''>0 0 -0.0035 3.14159 -0 3.14159</pose>
          <geometry>
            <cylinder>
              <length>0.2</length>
              <radius>0.33</radius>
            </cylinder>
          </geometry>
          <surface>
            <contact>
              <ode/>
            </contact>
            <friction>
              <ode>
                <mu>1.2</mu>
                <mu2>1.2</mu2>
              </ode>
              <torsional>
                <ode/>
              </torsional>
            </friction>
            <bounce/>
          </surface>
          <max_contacts>10</max_contacts>
        </collision>
        <visual name='wheel_fr_visual_visual'>
          <pose frame=''>0 0 -0.043777 3.14159 1.57079 -1.57079</pose>
          <geometry>
            <mesh>
              <scale>1 1 1</scale>
              <uri>/home/lucas/dbw_ws/src/dbw_mkz_ros/dbw_mkz_description/meshes/mkz_13/wheel.dae</uri>
            </mesh>
          </geometry>
          <material>
            <script>
              <uri>__default__</uri>
              <name>__default__</name>
            </script>
          </material>
        </visual>
        <gravity>1</gravity>
        <velocity_decay/>
        <self_collide>0</self_collide>
        <kinematic>0</kinematic>
      </link>
      <joint name='wheel_fr' type='revolute'>
        <child>wheel_fr</child>
        <parent>steer_fr</parent>
        <axis>
          <xyz>0 1 0</xyz>
          <limit>
            <lower>-1e+16</lower>
            <upper>1e+16</upper>
          </limit>
          <dynamics>
            <spring_reference>0</spring_reference>
            <spring_stiffness>0</spring_stiffness>
          </dynamics>
          <use_parent_model_frame>1</use_parent_model_frame>
        </axis>
        <physics>
          <ode>
            <limit>
              <cfm>0</cfm>
              <erp>0.2</erp>
            </limit>
          </ode>
        </physics>
      </joint>
      <link name='wheel_rl'>
        <pose frame=''>0 0.7874 0.33 1.5708 -0 3.14159</pose>
        <inertial>
          <pose frame=''>0 0 0 3.14159 -0 3.14159</pose>
          <mass>10</mass>
          <inertia>
            <ixx>0.305583</ixx>
            <ixy>0</ixy>
            <ixz>0</ixz>
            <iyy>0.305583</iyy>
            <iyz>0</iyz>
            <izz>0.5445</izz>
          </inertia>
        </inertial>
        <collision name='wheel_rl_collision_collision'>
          <pose frame=''>0 0 -0.021118 3.14159 -0 3.14159</pose>
          <geometry>
            <cylinder>
              <length>0.2</length>
              <radius>0.33</radius>
            </cylinder>
          </geometry>
          <surface>
            <contact>
              <ode/>
            </contact>
            <friction>
              <ode>
                <mu>1.2</mu>
                <mu2>1.2</mu2>
              </ode>
              <torsional>
                <ode/>
              </torsional>
            </friction>
            <bounce/>
          </surface>
          <max_contacts>10</max_contacts>
        </collision>
        <visual name='wheel_rl_visual_visual'>
          <pose frame=''>0 0 0.017382 3.14159 -1.57079 1.57079</pose>
          <geometry>
            <mesh>
              <scale>1 1 1</scale>
              <uri>/home/lucas/dbw_ws/src/dbw_mkz_ros/dbw_mkz_description/meshes/mkz_13/wheel.dae</uri>
            </mesh>
          </geometry>
          <material>
            <script>
              <uri>__default__</uri>
              <name>__default__</name>
            </script>
          </material>
        </visual>
        <gravity>1</gravity>
        <velocity_decay/>
        <self_collide>0</self_collide>
        <kinematic>0</kinematic>
      </link>
      <joint name='wheel_rl' type='revolute'>
        <child>wheel_rl</child>
        <parent>base_footprint</parent>
        <axis>
          <xyz>0 1 0</xyz>
          <limit>
            <lower>-1e+16</lower>
            <upper>1e+16</upper>
          </limit>
          <dynamics>
            <spring_reference>0</spring_reference>
            <spring_stiffness>0</spring_stiffness>
          </dynamics>
          <use_parent_model_frame>1</use_parent_model_frame>
        </axis>
        <physics>
          <ode>
            <limit>
              <cfm>0</cfm>
              <erp>0.2</erp>
            </limit>
          </ode>
        </physics>
      </joint>
      <link name='wheel_rr'>
        <pose frame=''>0 -0.7874 0.33 1.5708 -0 3.14159</pose>
        <inertial>
          <pose frame=''>0 0 0 3.14159 -0 3.14159</pose>
          <mass>10</mass>
          <inertia>
            <ixx>0.305583</ixx>
            <ixy>0</ixy>
            <ixz>0</ixz>
            <iyy>0.305583</iyy>
            <iyz>0</iyz>
            <izz>0.5445</izz>
          </inertia>
        </inertial>
        <collision name='wheel_rr_collision_collision'>
          <pose frame=''>0 0 0.0205 3.14159 -0 3.14159</pose>
          <geometry>
            <cylinder>
              <length>0.2</length>
              <radius>0.33</radius>
            </cylinder>
          </geometry>
          <surface>
            <contact>
              <ode/>
            </contact>
            <friction>
              <ode>
                <mu>1.2</mu>
                <mu2>1.2</mu2>
              </ode>
              <torsional>
                <ode/>
              </torsional>
            </friction>
            <bounce/>
          </surface>
          <max_contacts>10</max_contacts>
        </collision>
        <visual name='wheel_rr_visual_visual'>
          <pose frame=''>0 0 -0.019214 3.14159 1.57079 -1.57079</pose>
          <geometry>
            <mesh>
              <scale>1 1 1</scale>
              <uri>/home/lucas/dbw_ws/src/dbw_mkz_ros/dbw_mkz_description/meshes/mkz_13/wheel.dae</uri>
            </mesh>
          </geometry>
          <material>
            <script>
              <uri>__default__</uri>
              <name>__default__</name>
            </script>
          </material>
        </visual>
        <gravity>1</gravity>
        <velocity_decay/>
        <self_collide>0</self_collide>
        <kinematic>0</kinematic>
      </link>
      <joint name='wheel_rr' type='revolute'>
        <child>wheel_rr</child>
        <parent>base_footprint</parent>
        <axis>
          <xyz>0 1 0</xyz>
          <limit>
            <lower>-1e+16</lower>
            <upper>1e+16</upper>
          </limit>
          <dynamics>
            <spring_reference>0</spring_reference>
            <spring_stiffness>0</spring_stiffness>
          </dynamics>
          <use_parent_model_frame>1</use_parent_model_frame>
        </axis>
        <physics>
          <ode>
            <limit>
              <cfm>0</cfm>
              <erp>0.2</erp>
            </limit>
          </ode>
        </physics>
      </joint>
      <plugin name='dbw_interface_plugin' filename='libdbw_mkz_gazebo_vehicle.so'>
        <start_gear>4</start_gear>
        <car_model>mkz</car_model>
        <car_year>2013</car_year>
        <robotNamespace>mkz</robotNamespace>
      </plugin>
      <plugin name='pose_plugin' filename='libdbw_mkz_gazebo_pose.so'>
        <pub_tf>1</pub_tf>
        <pub_odom>1</pub_odom>
        <robotNamespace>mkz</robotNamespace>
      </plugin>
      <static>0</static>
      <plugin name='gps_plugin' filename='libdbw_mkz_gazebo_gps.so'>
        <link_name>perfect_gps</link_name>
        <update_rate>50.0</update_rate>
        <ref_lat>45.0</ref_lat>
        <ref_lon>-81.0</ref_lon>
        <ant_offset_x>0.6</ant_offset_x>
        <ant_offset_y>0</ant_offset_y>
        <ant_offset_z>1.45</ant_offset_z>
        <robotNamespace>mkz</robotNamespace>
      </plugin>
      <pose frame=''>0 0 0 0 -0 0</pose>
    </model>
  </world>
</sdf>
